{"name": "Test to verify that user gets expected error message when trying to complete task having interlocks and task action configured on same task start", "status": "passed", "description": "This test case tests that the user gets expected error message when trying to complete task", "parameters": [{"name": "job_execution_by", "value": "'user'"}, {"name": "users_list", "value": "['process.publisher.03']"}], "start": 1733759966634, "stop": 1733759984572, "uuid": "88471e1f-2352-4619-885f-c9d53f6d1924", "historyId": "ffb0cff4549c93ea564a383ead877dc4", "testCaseId": "abf0ba146224e483cc07ad9986161d20", "fullName": "tests.scenarios.job.test_interlocks_execution.TestInterlocksExecution#test_validate_expected_error_while_execution_of_task_interlocks_and_task_action_automations_on_same_task", "labels": [{"name": "tag", "value": "validate_expected_error_while_execution_of_task_interlocks_and_task_action_automations_on_same_task"}, {"name": "tag", "value": "task_action_automations"}, {"name": "tag", "value": "interlocks"}, {"name": "tag", "value": "job"}, {"name": "tag", "value": "scenario"}, {"name": "parentSuite", "value": "tests.scenarios.job"}, {"name": "suite", "value": "test_interlocks_execution"}, {"name": "subSuite", "value": "TestInterlocksExecution"}, {"name": "host", "value": "ubuntu"}, {"name": "thread", "value": "53959-MainThread"}, {"name": "framework", "value": "pytest"}, {"name": "language", "value": "cpython3"}, {"name": "package", "value": "tests.scenarios.job.test_interlocks_execution"}], "links": [{"type": "link", "url": "https://app.clickup.com/t/86curqb3r", "name": "https://app.clickup.com/t/86curqb3r"}]}